<?xml version="1.0"?>
<robot name="swan_k1_hwing">
	<link name="base">
    <visual>
      <!-- <origin rpy="0 -1.57 0" xyz="0 0 0"/> -->
      <origin rpy="0 0 0" xyz="0 0 0"/>
      <geometry>
        <!-- <mesh filename="../meshes/swan_k1_hwing_fuselage.dae" scale="1 1 1"/> -->
        <box size="0.04 0.2 0.4"/> 
      </geometry>
    </visual>
    <collision>
        <!-- <mesh filename="../meshes/swan_k1_hwing_fuselage.dae" scale="1 1 1"/> -->
        <box size="0.04 0.2 0.4"/>
    </collision> 
    <inertial>
      <mass value="1.5"/>
      <inertia ixx="0.025" ixy="0.0" ixz="0.0" iyy="0.0202" iyz="0.0" izz="0.0052"/>
    </inertial>
  </link>
  <link name="wing_left">
    <visual>
      <origin rpy="0 0 0" xyz="0 0 0"/>
      <geometry>
        <box size="0.01 0.5 0.2"/>
      </geometry>
    </visual>
    <inertial>
      <mass value="0.1"/>
      <inertia ixx="0.0021667" ixy="0.0" ixz="0.0" iyy="0.00008417" iyz="0.0" izz="0.002084167"/>
    </inertial>
  </link>
  <link name="wing_right">
    <visual>
      <origin rpy="0 0 0" xyz="0 0 0"/>
      <geometry>
        <box size="0.01 0.5 0.2"/>
      </geometry>
    </visual>
    <inertial>
      <mass value="0.1"/>
      <inertia ixx="0.0021667" ixy="0.0" ixz="0.0" iyy="0.000084167" iyz="0.0" izz="0.002084167"/>
    </inertial>
  </link>
	<link name="winglet_left">
    <visual>
      <origin rpy="0 0 1.5707963 " xyz="0 0 0"/>
      <geometry>
        <box size="0.005 0.08 0.085"/>
      </geometry>
    </visual>
    <inertial>
      <mass value="0.005"/>
      <inertia ixx="0.000005677" ixy="0.0" ixz="0.0" iyy="0.000003021" iyz="0.0" izz="0.000002677"/>
    </inertial>
  </link>
  	<link name="winglet_right">
    <visual>
      <origin rpy="0 0 1.5707963" xyz="0 0 0"/>
      <geometry>
        <box size="0.005 0.08 0.085"/>
      </geometry>
    </visual>
    <inertial>
      <mass value="0.005"/>
      <inertia ixx="0.000005677" ixy="0.0" ixz="0.0" iyy="0.000003021" iyz="0.0" izz="0.000002677"/>
    </inertial>
  </link>
	<link name="vstab_r">
    <visual>
      <origin rpy="0 0 1.57079632679" xyz="0 -0.25 -0.06"/>
      <geometry>
        <box size="0.01 0.3 0.03"/>
      </geometry>
    </visual>
    <inertial>
      <mass value="0.005"/>
      <inertia ixx="0.000037875" ixy="0.0" ixz="0.0" iyy="0.0000004167" iyz="0.0" izz="0.00003754"/>
    </inertial>
  </link>
  <link name="vstab_l">
    <visual>
      <origin rpy="0 0 1.57079632679" xyz="0 0.25 -0.06"/>
      <geometry>
        <box size="0.01 0.3 0.03"/>
      </geometry>
    </visual>
    <inertial>
      <mass value="0.005"/>
      <inertia ixx="0.000037875" ixy="0.0" ixz="0.0" iyy="0.0000004167" iyz="0.0" izz="0.00003754"/>
    </inertial>
  </link>
  <link name="leg1">
    <visual>
      <origin rpy="0 0 0" xyz="-0.16 -0.25 -0.26"/>
      <geometry>
        <sphere radius="0.01"/>
      </geometry>
    </visual>
    <collision>
      <origin rpy="0 0 0" xyz="-0.16 -0.25 -0.26"/>
      <geometry>
        <sphere radius="0.01"/>
      </geometry>
    </collision>
  </link>
  <link name="leg2">
    <visual>
      <origin rpy="0 0 0" xyz="0.16 0.25 -0.26"/>
      <geometry>
        <sphere radius="0.01"/>
      </geometry>
    </visual>
    <collision>
      <origin rpy="0 0 0" xyz="0.16 0.25 -0.26"/>
      <geometry>
        <sphere radius="0.01"/>
      </geometry>
    </collision>
  </link>
  <link name="leg3">
    <visual>
      <origin rpy="0 0 0" xyz="-0.16 0.25 -0.26"/>
      <geometry>
        <sphere radius="0.01"/>
      </geometry>
    </visual>
    <collision>
      <origin rpy="0 0 0" xyz="-0.16 0.25 -0.26"/>
      <geometry>
        <sphere radius="0.01"/>
      </geometry>
    </collision>
  </link>
  <link name="leg4">
    <visual>
      <origin rpy="0 0 0" xyz="0.16 -0.25 -0.26"/>
      <geometry>
        <sphere radius="0.01"/>
      </geometry>
    </visual>
    <collision>
      <origin rpy="0 0 0" xyz="0.16 -0.25 -0.26"/>
      <geometry>
        <sphere radius="0.01"/>
      </geometry>
    </collision>
  </link>

  <joint name="j_wing_left" type="fixed">
      <origin rpy="0 0 0" xyz="0 0.35 -0.05"/>
      <parent link="base"/>
      <child link="wing_left"/>
  </joint>
  <joint name="j_wing_right" type="fixed">
      <origin rpy="0 0 0" xyz="0 -0.35 -0.05"/>
      <parent link="base"/>
      <child link="wing_right"/>
  </joint>
  <joint name="j_winglet_left" type="fixed">
      <origin rpy="0 0 0" xyz="-0.04 0.25 -0.1"/>
      <parent link="wing_left"/>
      <child link="winglet_left"/>
  </joint>
  <joint name="j_winglet_right" type="fixed">
      <origin rpy="0 0 0" xyz="-0.04 -0.25 -0.1"/>
      <parent link="wing_right"/>
      <child link="winglet_right"/>
  </joint>
  <joint name="j_leg1" type="fixed">
      <parent link="base"/>
      <child link="leg1"/>
  </joint>
  <joint name="j_leg2" type="fixed">
      <parent link="base"/>
      <child link="leg2"/>
  </joint>
  <joint name="j_leg3" type="fixed">
      <parent link="base"/>
      <child link="leg3"/>
  </joint>
  <joint name="j_leg4" type="fixed">
      <parent link="base"/>
      <child link="leg4"/>
  </joint>

  <!-- CCW -->
  <link name="motor1_link">
    <inertial>
      <mass value="0.025"/>
      <inertia ixx="0.000260417" ixy="0.0" ixz="0.0" iyy="0.000130417" iyz="0.0" izz="0.000130417"/>
    </inertial>
    <collision name="motor_collision">
      <origin rpy="0 0 0" xyz="0 0 0"/>
      <geometry>
        <cylinder length="0.0178" radius="0.0112"/>
      </geometry>
    </collision>
    <visual name="motor_visual">
      <geometry>
        <cylinder length="0.0178" radius="0.0112"/>
      </geometry>
    </visual>
  </link>
  <!-- <link name="prop1">
    <collision name="prop_collision">
      <origin rpy="0 0 0" xyz="0 0 0.022"/>
      <geometry>
        <cylinder length="0.005" radius="0.13"/>
      </geometry>
    </collision>
    <visual name='prop_visual'>
      <origin rpy="0 0 0" xyz="0 0 0.015"/>
      <geometry>
        <mesh filename="../meshes/swan_k1_hwing/iris_prop_ccw.dae" scale="1 1 1"/>
        <cylinder length="0.005" radius="0.13"/>
      </geometry>
    </visual>
  </link> -->
  <joint name="motor1_joint" type="revolute">
    <origin rpy="0.174532925 0.174532925 0" xyz="-0.16 -0.25 -0.015"/>
    <parent link="base"/>
    <child link="motor1_link"/>
    <axis xyz="0 0 1"/>
    <limit lower="-3.14159" upper="3.14159"/>
    <dynamics damping="0.004"/>
  </joint>
  <!-- <joint name="j_m1" type="fixed">
       <parent link="motor1_link"/>
       <child link="prop1"/>
  </joint> -->

  <!-- CCW -->
  <link name="motor2_link">
    <inertial>
      <mass value="0.025"/>
      <inertia ixx="0.000260417" ixy="0.0" ixz="0.0" iyy="0.000130417" iyz="0.0" izz="0.000130417"/>
    </inertial>
    <collision name="motor_collision">
      <origin rpy="0 0 0" xyz="0 0 0"/>
      <geometry>
        <cylinder length="0.0178" radius="0.0112"/>
      </geometry>
    </collision>
    <visual name="motor_visual">
      <geometry>
        <cylinder length="0.0178" radius="0.0112"/>
      </geometry>
    </visual>
  </link>
  <!-- <link name="prop2">
    <collision name="prop_collision">
      <origin rpy="0 0 0" xyz="0 0 0.022"/>
      <geometry>
        <cylinder length="0.005" radius="0.13"/>
      </geometry>
    </collision>
    <visual name='prop_visual'>
      <origin rpy="0 0 0" xyz="0 0 0.015"/>
      <geometry>
        <mesh filename="../meshes/swan_k1_hwing/iris_prop_ccw.dae" scale="1 1 1"/>
        <cylinder length="0.005" radius="0.13"/>
      </geometry>
    </visual>
  </link> -->
  <joint name='motor2_joint' type='revolute'>
    <origin rpy="-0.174532925 -0.174532925 0" xyz="0.16 0.25 -0.015"/>
    <parent link="base"/>
    <child link="motor2_link"/>
    <axis xyz="0 0 1"/>
    <limit lower="-3.14159" upper="3.14159"/>
    <dynamics damping="0.004"/>
  </joint>
  <!-- <joint name="j_m2" type="fixed">
       <parent link="motor2_link"/>
       <child link="prop2"/>
  </joint> -->

  <!-- CW -->
  <link name="motor3_link">
    <inertial>
      <mass value="0.025"/>
      <inertia ixx="0.000260417" ixy="0.0" ixz="0.0" iyy="0.000130417" iyz="0.0" izz="0.000130417"/>
    </inertial>
    <collision name="motor_collision">
      <origin rpy="0 0 0" xyz="0 0 0"/>
      <geometry>
        <cylinder length="0.0178" radius="0.0112"/>
      </geometry>
    </collision>
    <visual name="motor_visual">
      <geometry>
        <cylinder length="0.0178" radius="0.0112"/>
      </geometry>
    </visual>
  </link>
  <!-- <link name="prop3">
    <collision name="prop_collision">
      <origin rpy="0 0 0" xyz="0 0 0.022"/>
      <geometry>
        <cylinder length="0.005" radius="0.13"/>
      </geometry>
    </collision>
    <visual name='prop_visual'>
      <origin rpy="0 0 0" xyz="0 0 0.015"/>
      <geometry>
        <mesh filename="../meshes/swan_k1_hwing/iris_prop_cw.dae" scale="1 1 1"/>
        <cylinder length="0.005" radius="0.13"/>
      </geometry>
    </visual>
  </link> -->
  <joint name='motor3_joint' type='revolute'>
    <origin rpy="-0.174532925 0.174532925 0" xyz="-0.16 0.25 -0.015"/>
    <parent link="base"/>
    <child link="motor3_link"/>
    <axis xyz="0 0 1"/>
    <limit lower="-3.14159" upper="3.14159"/>
    <dynamics damping="0.004"/>
  </joint>
  <!-- <joint name="j_m3" type="fixed">
       <parent link="motor3_link"/>
       <child link="prop3"/>
  </joint> -->

  <!-- CW -->
  <link name="motor4_link">
    <inertial>
      <mass value="0.025"/>
      <inertia ixx="0.000260417" ixy="0.0" ixz="0.0" iyy="0.000130417" iyz="0.0" izz="0.000130417"/>
    </inertial>
    <collision name="motor_collision">
      <origin rpy="0 0 0" xyz="0 0 0"/>
      <geometry>
        <cylinder length="0.0178" radius="0.0112"/>
      </geometry>
    </collision>
    <visual name="motor_visual">
      <geometry>
        <cylinder length="0.0178" radius="0.0112"/>
      </geometry>
    </visual>
  </link>
  <!-- <link name="prop4">
    <collision name="prop_collision">
      <origin rpy="0 0 0" xyz="0 0 0.022"/>
      <geometry>
        <cylinder length="0.005" radius="0.13"/>
      </geometry>
    </collision>
    <visual name='prop_visual'>
      <origin rpy="0 0 0" xyz="0 0 0.015"/>
      <geometry>
        <mesh filename="../meshes/swan_k1_hwing/iris_prop_cw.dae" scale="1 1 1"/>
        <cylinder length="0.005" radius="0.13"/>
      </geometry>
    </visual>
  </link> -->
  <joint name="motor4_joint" type="revolute">
    <origin rpy="0.174532925 -0.174532925 0" xyz="0.16 -0.25 -0.015"/>
    <parent link="base"/>
    <child link="motor4_link"/>
    <axis xyz="0 0 1"/>
    <limit lower="-3.14159" upper="3.14159"/>
    <dynamics damping="0.004"/>
  </joint>
  <!-- <joint name="j_m4" type="fixed">
       <parent link="motor4_link"/>
       <child link="prop4"/>
  </joint> -->
</robot>
