<?xml version="1.0"?>

<robot name="f450">
  <link name="base">
    <visual>
      <origin xyz="0 0 0" rpy="0 0 0" />
      <geometry>
        <cylinder length="0.05" radius="0.1" />
      </geometry>
    </visual>
    <collision>
      <origin xyz="0 0 0" rpy="0 0 0" />
      <geometry>
        <cylinder length="0.05" radius="0.1" />
      </geometry>
    </collision>
    <inertial>
      <mass value="1.4" />
      <inertia ixx="0.014291666666666668" ixy="0.0" ixz="0.0" iyy="0.014291666666666668" iyz="0.0" izz="0.028" />
    </inertial>
  </link>

  <!-- CCW -->
  <link name="FL">
    <visual>
      <geometry>
        <cylinder length="0.005" radius="0.1" />
      </geometry>
    </visual>
    <collision>
      <geometry>
        <cylinder length="0.005" radius="0.1" />
      </geometry>
    </collision>
    <inertial>
      <mass value="0.00005" />
      <inertia ixx="9.7499961e-07" ixy="0.0" ixz="0.0" iyy="4.170414998500001e-05" iyz="0.0" izz="4.2604149625000006e-05" />
    </inertial>
  </link>
  <joint name="base_to_FL" type="revolute">
    <origin xyz="0.16 0.16 0.038" rpy="0 0 0" />
    <parent link="base" />
    <child link="FL" />
    <axis xyz="0 0 1"/>
    <limit lower="-3.14159" upper="3.14159"/>
    <dynamics damping="0.004"/>
  </joint>

  <!-- CW -->
  <link name="BL">
    <visual>
      <geometry>
        <cylinder length="0.005" radius="0.1" />
      </geometry>
    </visual>
    <collision>
      <geometry>
        <cylinder length="0.005" radius="0.1" />
      </geometry>
    </collision>
    <inertial>
      <mass value="0.00005" />
      <inertia ixx="9.7499961e-07" ixy="0.0" ixz="0.0" iyy="4.170414998500001e-05" iyz="0.0" izz="4.2604149625000006e-05" />
    </inertial>
  </link>
  <joint name="base_to_BL" type="revolute">
    <origin xyz="-0.16 0.16 0.038" rpy="0 0 0" />
    <parent link="base" />
    <child link="BL" />
    <axis xyz="0 0 1"/>
    <limit lower="-3.14159" upper="3.14159"/>
    <dynamics damping="0.004"/>
  </joint>

  <!-- CCW -->
  <link name="BR">
    <visual>
      <geometry>
        <cylinder length="0.005" radius="0.1" />
      </geometry>
    </visual>
    <collision>
      <geometry>
        <cylinder length="0.005" radius="0.1" />
      </geometry>
    </collision>
    <inertial>
      <mass value="0.00005" />
      <inertia ixx="9.7499961e-07" ixy="0.0" ixz="0.0" iyy="4.170414998500001e-05" iyz="0.0" izz="4.2604149625000006e-05" />
    </inertial>
  </link>
  <joint name="base_to_BR" type="revolute">
    <origin xyz="-0.16 -0.16 0.038" rpy="0 0 0" />
    <parent link="base" />
    <child link="BR" />
    <axis xyz="0 0 1"/>
    <limit lower="-3.14159" upper="3.14159"/>
    <dynamics damping="0.004"/>
  </joint>

  <!-- CW -->
  <link name="FR">
    <visual>
      <geometry>
        <cylinder length="0.005" radius="0.1" />
      </geometry>
    </visual>
    <collision>
      <geometry>
        <cylinder length="0.005" radius="0.1" />
      </geometry>
    </collision>
    <inertial>
      <mass value="0.00005" />
      <inertia ixx="9.7499961e-07" ixy="0.0" ixz="0.0" iyy="4.170414998500001e-05" iyz="0.0" izz="4.2604149625000006e-05" />
    </inertial>
  </link>
  <joint name="base_to_FR" type="revolute">
    <origin xyz="0.16 -0.16 0.038" rpy="0 0 0" />
    <parent link="base" />
    <child link="FR" />
    <axis xyz="0 0 1"/>
    <limit lower="-3.14159" upper="3.14159"/>
    <dynamics damping="0.004"/>
  </joint>


  <gazebo reference="base">
    <material>Gazebo/Blue</material>
    <turnGravityOff>true</turnGravityOff>
  </gazebo>
</robot>