<?xml version="1.0"?>
<robot name="iris">
  <link name="base">
    <visual>
      <origin xyz="0 0 0" rpy="0 0 0" />
      <geometry>
        <box size="0.23 0.23 0.05" />
      </geometry>
    </visual>
    <collision>
      <origin xyz="0 0 0" rpy="0 0 0" />
      <geometry>
        <box size="0.47 0.47 0.11" />
      </geometry>
    </collision>
    <inertial>
      <mass value="1.5" /> 
      <inertia ixx="0.0347563" ixy="0.0" ixz="0.0" iyy="0.0458929" iyz="0.0" izz="0.0977" />
    </inertial>
  </link>

  <!-- CCW -->
  <link name="FL">
    <visual>
      <geometry>
        <cylinder length="0.005" radius="0.1" />
      </geometry>
    </visual>
    <collision>
      <geometry>
        <cylinder length="0.005" radius="0.1" />
      </geometry>
    </collision>
    <inertial>
      <mass value="0.00005" />
      <inertia ixx="9.7499961e-07" ixy="0.0" ixz="0.0" iyy="4.170414998500001e-05" iyz="0.0" izz="4.2604149625000006e-05" />
    </inertial>
  </link>
  <joint name="base_to_FL" type="revolute">
    <origin xyz="0.22 0.13 0.023" rpy="0 0 0" />
    <parent link="base" />
    <child link="FL" />
    <axis xyz="0 0 1"/>
    <limit lower="-3.14159" upper="3.14159"/>
    <dynamics damping="0.004"/>
  </joint>

  <!-- CW -->
  <link name="BL">
    <visual>
      <geometry>
        <cylinder length="0.005" radius="0.1" />
      </geometry>
    </visual>
    <collision>
      <geometry>
        <cylinder length="0.005" radius="0.1" />
      </geometry>
    </collision>
    <inertial>
      <mass value="0.00005" />
      <inertia ixx="9.7499961e-07" ixy="0.0" ixz="0.0" iyy="4.170414998500001e-05" iyz="0.0" izz="4.2604149625000006e-05" />
    </inertial>
  </link>
  <joint name="base_to_BL" type="revolute">
    <origin xyz="-0.22 0.13 0.023" rpy="0 0 0" />
    <parent link="base" />
    <child link="BL" />
    <axis xyz="0 0 1"/>
    <limit lower="-3.14159" upper="3.14159"/>
    <dynamics damping="0.004"/>
  </joint>

  <!-- CCW -->
  <link name="BR">
    <visual>
      <geometry>
        <cylinder length="0.005" radius="0.1" />
      </geometry>
    </visual>
    <collision>
      <geometry>
        <cylinder length="0.005" radius="0.1" />
      </geometry>
    </collision>
    <inertial>
      <mass value="0.00005" />
      <inertia ixx="9.7499961e-07" ixy="0.0" ixz="0.0" iyy="4.170414998500001e-05" iyz="0.0" izz="4.2604149625000006e-05" />
    </inertial>
  </link>
  <joint name="base_to_BR" type="revolute">
    <origin xyz="-0.22 -0.13 0.023" rpy="0 0 0" />
    <parent link="base" />
    <child link="BR" />
    <axis xyz="0 0 1"/>
    <limit lower="-3.14159" upper="3.14159"/>
    <dynamics damping="0.004"/>
  </joint>

  <!-- CW -->
  <link name="FR">
    <visual>
      <geometry>
        <cylinder length="0.005" radius="0.1" />
      </geometry>
    </visual>
    <collision>
      <geometry>
        <cylinder length="0.005" radius="0.1" />
      </geometry>
    </collision>
    <inertial>
      <mass value="0.00005" />
      <inertia ixx="9.7499961e-07" ixy="0.0" ixz="0.0" iyy="4.170414998500001e-05" iyz="0.0" izz="4.2604149625000006e-05" />
    </inertial>
  </link>
  <joint name="base_to_FR" type="revolute">
    <origin xyz="0.22 -0.13 0.023" rpy="0 0 0" />
    <parent link="base" />
    <child link="FR" />
    <axis xyz="0 0 1"/>
    <limit lower="-3.14159" upper="3.14159"/>
    <dynamics damping="0.004"/>
  </joint>


  <gazebo reference="base">
    <material>Gazebo/Blue</material>
    <turnGravityOff>true</turnGravityOff>
  </gazebo>
</robot>